Workbook

Sheet Instructions
A1: Instructions
A3: To perform the GRADE assessment the following is needed: 1) NMA estimates and 95% confidence or credible intervals (we abbreviate either from now on as CI) for every comparison using both relative and absolute estimates of effect; 2) Direct and indirect estimates and 95% CI for each comparison; 3) Risk of bias assessments for each outcome; 4) Forest plots of all direct comparisons; 5) network plot for each outcome.
A5: 1) Set your preferences
A7: 2) Clear the spreadsheet. This step can be automatically performed by clicking RESET in cell A1 of "Primary - GRADING sheet"
A9: 3) Include the comparisons that needs to be assessed (GRADED) in columns B and C. If a reference intervention is available (e.g placebo) always include it as treatment 2 (column C). Incorporate estimates of effect (relative and absolute [per 1000 treated patients]) for every comparison. Include direct (when available)(columns E to J) , indirect (columns T to Y) and NMA estimates of effects (columns AV to BA). For those comparisons for which estimates are not available use "NA" as in the example provided.
A11: 4) For every comparison for which direct estimates of effect are available, assess risk of bias, incosistency, indirectness and publication bias. Imprecision for direct estimate can also be performed at this stage for which an automatic option is available in preferences.
A13: 5) Select common comparator (first order loop) or common comparator + middle comparator (second order loop) for every comparison for which indirect estimates of effect are available.
A15: 6) Asses intransitivity. Imprecision for indirect estimate can also be performed at this stage for which an automatic option is available in preferences.
A17: 7) Select source to inform NMA (direct vs indirect). Automatic option available in preferences.
A19: 8) Assess Incoherence
A21: 9) Assess imprecision for NMA estimate. Automatic option available in preferences.
A23: 10) Assess imprecision for direct and indirect estimates if required and not performed previously. Automatic option available in preferences.
... A29: © 2022 Ariel Izcovich. All rights reserved

Sheet Preferences
A1: Preferences
A3: Inmprecision assessment | B3: Automatic
A5: Small effect threshold per 1000 patients treated | B5: 20
A7: Large effect threshold per 1000 patients treated | B7: 100
A9: Selection of the source to informe NMA (direct vs. indirect) | B9: Automatic
A11: Drawing conclusions: Classification | B11: Minimally contextualised framework
A13: Reference intevention | B13: Plac

Sheet Primary - GRADING
B1: Comparison | C1: Threshold per 1000 (small) | D1: =IF(Preferences!B3="Automatic",Preferences!B5,"NA") -> 20 | E1: Direct estimate | T1: Indirect estimate | AV1: Network estimate | CJ1: Baseline risk: 130 per 1000 (2021-08-17) | CL1: Direct dominant (FALSE=Dominant) | CM1: Indirect dominant (FALSE=Dominant) | CN1: Direct certainty to numbers | CO1: Indirect certainty to numbers | CP1: Vs reference
A2: Nr. | C2: Threshold per 1000 (Large) | D2: =IF(Preferences!B3="Automatic",Preferences!B7,"NA") -> 100 | E2: Relative estimate | H2: Absolute estimate (per 1,000) | L2: GRADE | T2: Relative estimate | W2: Absolute estimate (per 1,000) | AQ2: GRADE | AV2: Relative estimate | AY2: Absolute estimate (per 1,000) | BB2: GRADE | BN2: Automated Direct | BO2: Automated indirect | BP2: Reasons for downgrading (,) | BR2: RoB Tmt1 vs Compr | BS2: RoB Compr vs Middle | BT2: RoB Compr/middle vs Tmt2 | BU2: Indirect RoB Summary | BV2: Incosistency Tmt1 vs Compr | BW2: Incosistency Compr vs Middle | BX2: Incosistency Compr/middle vs Tmt2 | BY2: Incosistency RoB Summary | BZ2: Indirectness Tmt1 vs Compr | CA2: Indirectness Compr vs Middle | CB2: Indirectness Compr/middle vs Tmt2 | CC2: Indirectness Summary | CD2: Publication bias Tmt1 vs Compr | CE2: Publication bias Compr vs middle | CF2: Publication bias Tmt1 vs Compr/middle vs Tmt2 | CG2: Publication bias Summary | CH2: Imprecision Summary | CI2: Incoherence summary | CK2: 44549
B3: Treatment 1 | C3: Treatment 2 | E3: Point estimate | F3: CI lower limit | G3: CI upper limit | H3: Point estimate | I3: CI lower limit | J3: CI upper limit | L3: Risk of bias | M3: Inconsistency | N3: Indirectness | O3: Publication bias | P3: Rating for NMA | Q3: Imprecision | R3: Final rating | T3: Point estimate | U3: CI lower limit | V3: CI upper limit | W3: Point estimate | X3: CI lower limit | Y3: CI upper limit | AB3: Common comp | AC3: Comparison nr. | AD3: Tmt 1 vs comp | AG3: Middle comp | AH3: Comparison nr. | AI3: Comp vs middle | AN3: Comparison nr. | AO3: Tmt 2 vs comp/middle | AP3: Start rating | AQ3: Intransitivity | AR3: Rating for NMA | AS3: Imprecision | AT3: Final rating | AV3: Point estimate | AW3: CrI lower limit | AX3: CrI upper limit | AY3: Point estimate | AZ3: CI lower limit | BA3: CI upper limit | BB3: Starting evidence | BC3: Starting rating | BD3: Incoherence | BE3: Imprecision | BF3: Final rating | BG3: Best estimate | BH3: Significant effect | BI3: Risk of imprecision? | BJ3: Rating as a number | BK3: Significant effect NMA | BL3: Significant effect Direct | BM3: Significant effect Indirect | BN3: Reasons | BO3: =(IFERROR(IFS(BU3="RoB","RoB,",BU3="RoBx2","RoBx2,",BU3="NA",""),"")&IFERROR(IFS(BY3="RoB","Inconsistency,",BY3="RoBx2","Inconsistencyx2,",BY3="NA","")&IFERROR(IFS(CC3="RoB","Indirectness,",CC3="RoBx2","Indirectnessx2,",CC3="NA",""),"")&IFERROR(IFS(CG3="RoB","Publication bias,",CG3="RoBx2","Publication biasx2,",CG3="NA",""),"")&IFERROR(IFS(CH3="Serious","Imprecision,",CG3="Very serious","Imprecisionx2,",CH3="Extremely serious","Imprecisionx3",CH3="Not serious",""),"")&IFERROR(IFS(AQ3="Serious","Intransitivity,",AQ3="Very serious","Intransitivityx2,",AQ3="NA",""),"")&IFERROR(IFS(BD3="Serious","Incoherence,",BD3="Very serious","Incoherencex2,",BD3="NA",""),""))) | BQ3: Reasons for downgrading auto-calculator | CJ3: OIS Prelim Calculator | CK3: PRELIM Test incoherence calculator
A4: =IF(ISBLANK(B4),"",1) -> 1 | B4: A | C4: Plac | E4: 2.8536585 | F4: 0.093250995 | G4: 87.324998 | H4: 54.589891 | I4: -29.152469 | J4: 712.00314 | L4: Not serious | M4: Not serious | N4: Not serious | O4: Not serious | P4: =IF(OR(ISBLANK(L4),ISBLANK(M4),ISBLANK(N4),ISBLANK(O4)),"",if(OR(iserror(L4)=TRUE,iferror(L4="NA","NA")),"NA",ifs(4-(2*COUNTIF(L4:O4,"Very serious"))-countif(L4:O4,"Serious")=4,"HIGH",4-(2*COUNTIF(L4:O4,"Very serious"))-countif(L4:O4,"Serious")=3,"MODERATE",4-(2*COUNTIF(L4:O4,"Very serious"))-countif(L4:O4,"Serious")=2,"LOW",4-(2*COUNTIF(L4:O4,"Very serious"))-countif(L4:O4,"Serious")<=1,"VERY LOW"))) -> HIGH | Q4: =IFERROR(IF(AND(Preferences!B$3="Manual",OR(AX4/AW4>G4/F4,BD4="Serious",BD4="Very serious")),"Assess imprecision",IFS(ISBLANK(E4),"",AND(Preferences!B$3="Automatic", G4/F4>=30),"Extremely serious",AND(H4<=$D$1*-1,J4<0,G4/F4<3),"Not serious",AND(H4<=$D$1*-1,J4<0,G4/F4>=3),"Very serious",AND(H4>=$D$1,I4>0,G4/F4<3),"Not serious",AND(H4>=$D$1,I4>0,G4/F4>=3),"Very serious",AND(H4<=$D$1*-1,J4>0,I4>$D$2*-1,G4/F4<3),"Serious", AND(H4<=$D$1*-1,J4>0,I4<$D$2*-1,G4/F4<3),"Very serious", AND(H4>=$D$1,I4<0,J4<$D$2,G4/F4<3),"Serious",AND(H4>=$D$1,I4<0,J4>$D$2,G4/F4<3),"Very serious", AND(H4<=$D$1*-1,J4>0,I4>$D$2*-1,G4/F4>=3),"Very serious", AND(H4<=$D$1*-1,J4>0,I4<$D$2*-1,G4/F4>=3),"Very serious", AND(H4>=$D$1,I4<0,J4<$D$2,G4/F4>=3),"Very serious", AND(H4>=$D$1,I4<0,J4>$D$2,G4/F4>=3),"Very serious", AND(H4>$D$1*-1,H4<$D$1,I4>$D$1*-1,J4<$D$1,G4/F4<3),"Not serious", AND(H4>$D$1*-1,H4<$D$1,OR(I4<=$D$1*-1,J4>=$D$1),I4>$D$2*-1,J4<$D$2,G4/F4<3),"Serious", AND(H4>$D$1*-1,H4<$D$1,OR(I4<=$D$2*-1,J4>=$D$2),G4/F4<3),"Very serious", AND(H4>$D$1*-1,H4<$D$1,I4>$D$1*-1,J4<$D$1,G4/F4>=3),"Very serious", AND(H4>$D$1*-1,H4<$D$1,OR(I4<=$D$1*-1,J4>=$D$1),I4>$D$2*-1,J4<$D$2,G4/F4>=3),"Very serious", AND(H4>$D$1*-1,H4<$D$1,OR(I4<=$D$2*-1,J4>=$D$2),G4/F4>=3),"Very serious")),"") -> Extremely serious | R4: {=IFERROR(IFS(E4="NA","NA", AND(P4 = "HIGH",COUNTIF(Q4,"serious")>=1),"MODERATE", AND(P4 = "HIGH",COUNTIF(Q4,"Very serious")>=1),"LOW", AND(P4 = "HIGH",COUNTIF(Q4,"Extremely serious")>=1),"VERY LOW", AND(P4 = "HIGH",COUNTIF(Q4,"Not serious")>=1),P4, AND(P4 = "MODERATE",COUNTIF(Q4,"serious")>=1),"LOW", AND(P4 = "MODERATE",COUNTIF(Q4,"Very serious")>=1),"VERY LOW", AND(P4 = "MODERATE",COUNTIF(Q4,"Extremely serious")>=1),"VERY LOW", AND(P4 = "MODERATE",COUNTIF(Q4,"Not serious")>=1),P4, AND(P4 = "LOW",COUNTIF(Q4,"serious")>=1),"VERY LOW", AND(P4 = "LOW",COUNTIF(Q4,"Very serious")>=1),"VERY LOW", AND(P4 = "LOW",COUNTIF(Q4,"Extremely serious")>=1),"VERY LOW", AND(P4 = "LOW",COUNTIF(Q4,"Not serious")>=1),P4, P4 = "VERY LOW", P4),"")} -> VERY LOW | T4: NA | U4: NA | V4: NA | W4: NA | X4: NA | Y4: NA | Z4: {=INDEX($A$1:$C$500, MATCH(1,($B:$B=$B4)*($C:$C=$AB4),0),1)} -> #N/A | AA4: {=INDEX($A$1:$C$500, MATCH(1,($B:$B=$AB4)*($C:$C=$B4),0),1)} -> #N/A | AC4: =IF(ISNUMBER(Z4),Z4,AA4) -> #N/A | AD4: =IFERROR(INDEX($A$1:$R$500, MATCH(AC4,A:A,0),16),"") | AE4: {=INDEX($A$1:$C$500, MATCH(1,($B:$B=$AB4)*($C:$C=$AG4),0),1)} | AF4: {=INDEX($A$1:$C$500, MATCH(1,($B:$B=$AG4)*($C:$C=$AB4),0),1)} | AH4: =IF(ISNUMBER(AE4),AE4,AF4) | AI4: =IFERROR(INDEX($A$1:$R$500, MATCH(AH4,A:A,0),16),"") | AJ4: {=INDEX($A$1:$C$500, MATCH(1,($B:$B=$C4)*($C:$C=$AG4),0),1)} -> #N/A | AK4: {=INDEX($A$1:$C$500, MATCH(1,($B:$B=$AG4)*($C:$C=$C4),0),1)} -> #N/A | AL4: {=INDEX($A$1:$C$500, MATCH(1,($B:$B=$C4)*($C:$C=$AB4),0),1)} -> #N/A | AM4: {=INDEX($A$1:$C$500, MATCH(1,($B:$B=$AB4)*($C:$C=$C4),0),1)} -> #N/A | AN4: {=IFS(ISNUMBER(AJ4),AJ4,ISNUMBER(AK4),AK4,ISNUMBER(AL4),AL4,ISNUMBER(AM4),AM4)} -> #N/A | AO4: =IF(ISBLANK(AB4),"",INDEX($A$1:$R$500, MATCH(AN4,$A:$A,0),16)) | AP4: =IF(ISBLANK(AB4),"",iferror(if(or(ifna(AD4,1)=1,ifna(AO4,1)=1),"#N/A",if(countif({AO4,AD4},"VERY LOW")>=1,"VERY LOW",if(countif({AO4,AD4},"LOW")>=1,"LOW",if(countif({AO4,AD4},"MODERATE")>=1,"MODERATE",if(countif({AO4,AD4},"HIGH")>=1,"HIGH","Check manually"))))),"#N/A")) | AR4: =IF(OR(ISBLANK(AB4),ISBLANK(AQ4)),"",IFS(AND(AP4 = "HIGH",AQ4="Serious"),"MODERATE", AND(AP4 = "HIGH",AQ4="Not serious"),AP4, AND(AP4 = "MODERATE",AQ4="Serious"),"LOW", AND(AP4 = "MODERATE",AQ4 ="Not serious"),AP4, AND(AP4 = "LOW",AQ4="serious"),"VERY LOW", AND(AP4 = "LOW",AQ4="Not serious"),AP4, AND(AP4 = "HIGH",AQ4="Very serious"),"LOW", AND(AP4 = "MODERATE",AQ4="Very serious"),"VERY LOW", AND(AP4 = "LOW",AQ4="Very serious"),"VERY LOW", AP4 = "VERY LOW", AP4)) | AS4: =IFERROR(IF(AND(Preferences!B$3="Manual",OR(AX4/AW4>V4/U4,BD4="Serious",BD4="Very serious")),"Assess imprecision",IFERROR(IFS(AND(Preferences!B$3="Automatic",V4/U4>=30),"Extremely serious",AND(W4<=$D$1*-1,Y4<0,V4/U4<3),"Not Serious",AND(W4<=$D$1*-1,Y4<0,V4/U4>=3),"Very serious",AND(W4>=$D$1,X4>0,V4/U4<3),"Not Serious",AND(W4>=$D$1,X4>0,V4/U4>=3),"Very serious",AND(W4<=$D$1*-1,Y4>0,X4>$D$2*-1,V4/U4<3),"Serious", AND(W4<=$D$1*-1,Y4>0,X4<$D$2*-1,V4/U4<3),"Very serious", AND(W4>=$D$1,X4<0,Y4<$D$2,V4/U4<3),"Serious",AND(W4>=$D$1,X4<0,Y4>$D$2,V4/U4<3),"Very serious", AND(W4<=$D$1*-1,Y4>0,X4>$D$2*-1,V4/U4>=3),"Very serious", AND(W4<=$D$1*-1,Y4>0,X4<$D$2*-1,V4/U4>=3),"Very serious", AND(W4>=$D$1,X4<0,Y4<$D$2,V4/U4>=3),"Very serious", AND(W4>=$D$1,X4<0,Y4>$D$2,V4/U4>=3),"Very serious", AND(W4>$D$1*-1,W4<$D$1,X4>$D$1*-1,Y4<$D$1,V4/U4<3),"Not Serious", AND(W4>$D$1*-1,W4<$D$1,OR(X4<=$D$1*-1,Y4>=$D$1),X4>$D$2*-1,Y4<$D$2,V4/U4<3),"Serious", AND(W4>$D$1*-1,W4<$D$1,OR(X4<=$D$2*-1,Y4>=$D$2),V4/U4<3),"Very serious", AND(W4>$D$1*-1,W4<$D$1,X4>$D$1*-1,Y4<$D$1,V4/U4>=3),"Very serious", AND(W4>$D$1*-1,W4<$D$1,OR(X4<=$D$1*-1,Y4>=$D$1),X4>$D$2*-1,Y4<$D$2,V4/U4>=3),"Very serious", AND(W4>$D$1*-1,W4<$D$1,OR(X4<=$D$2*-1,Y4>=$D$2),V4/U4>=3),"Very serious"),"")),"") | AT4: =IFERROR(IFS(T4="NA","NA",AS4="","",AS4="Assess imprecision","", AND(AR4 = "HIGH",COUNTIF(AS4,"serious")>=1),"MODERATE", AND(AR4 = "HIGH",COUNTIF(AS4,"Very serious")>=1),"LOW", AND(AR4 = "HIGH",COUNTIF(AS4,"Extremely serious")>=1),"VERY LOW", AND(AR4 = "HIGH",COUNTIF(AS4,"Not serious")>=1),AR4, AND(AR4 = "MODERATE",COUNTIF(AS4,"serious")>=1),"LOW", AND(AR4 = "MODERATE",COUNTIF(AS4,"Very serious")>=1),"VERY LOW", AND(AR4 = "MODERATE",COUNTIF(AS4,"Extremely serious")>=1),"VERY LOW", AND(AR4 = "MODERATE",COUNTIF(AS4,"Not serious")>=1),AR4, AND(AR4 = "LOW",COUNTIF(AS4,"serious")>=1),"VERY LOW", AND(AR4 = "LOW",COUNTIF(AS4,"Very serious")>=1),"VERY LOW", AND(AR4 = "LOW",COUNTIF(AS4,"Extremely serious")>=1),"VERY LOW", AND(AR4 = "LOW",COUNTIF(AS4,"Not serious")>=1),AR4, AR4 = "VERY LOW", AR4),"") -> NA | AV4: 2.8536585 | AW4: 0.093250995 | AX4: 87.324998 | AY4: 54.589891 | AZ4: -29.152469 | BA4: 712.00314 | BB4: =IF(Preferences!B$9="Manual","",IFS(ISBLANK(B4),"",AND(ISNUMBER(E4)=TRUE,ISNUMBER(T4)=FALSE),"Direct", AND(ISNUMBER(E4)=FALSE,ISNUMBER(T4)=TRUE),"Indirect", CN4=4,"Direct",AND(CL4=FALSE, CM4=TRUE,CN4-CO4>-1),"Direct", AND(CL4=FALSE,CM4=TRUE, CN4-CO4<0),"Check algorithm in appendix 2", AND(CL4=TRUE, CM4=FALSE,CN4-CO4>0),"Check algorithm in appendix 2", AND(CL4=TRUE, CM4=FALSE,CN4-CO4=0),"Indirect", AND(CL4=TRUE, CM4=FALSE,CN4-CO4<0),"Indirect", AND(CL4=FALSE,CM4=FALSE,CN4-CO4>-1),"Direct", AND(CL4=FALSE,CM4=FALSE,CN4-CO4<0),"Check algorithm in appendix 2", AND(CL4=TRUE,CM4=TRUE,CN4-CO4>-1),"Direct", AND(CL4=TRUE,CM4=TRUE,CN4-CO4<0),"Check algorithm in appendix 2")) -> Direct | BC4: =IFS(BB4="Direct",P4,BB4="Indirect",AR4,BB4="","",BB4="Check algorithm in appendix 2","") -> HIGH | BD4: Not serious | BE4: =IF(Preferences!B$3="Manual","", IFERROR(IFS(AND(Preferences!B$3="Automatic",AX4/AW4>=30),"Extremely serious",AND(AY4<=$D$1*-1,BA4<0,AX4/AW4<3),"Not Serious",AND(AY4<=$D$1*-1,BA4<0,AX4/AW4>=3),"Very serious",AND(AY4>=$D$1,AZ4>0,AX4/AW4<3),"Not Serious",AND(AY4>=$D$1,AZ4>0,AX4/AW4>=3),"Very serious",AND(AY4<=$D$1*-1,BA4>0,AZ4>$D$2*-1,AX4/AW4<3),"Serious", AND(AY4<=$D$1*-1,BA4>0,AZ4<$D$2*-1,AX4/AW4<3),"Very serious", AND(AY4>=$D$1,AZ4<0,BA4<$D$2,AX4/AW4<3),"Serious",AND(AY4>=$D$1,AZ4<0,BA4>$D$2,AX4/AW4<3),"Very serious", AND(AY4<=$D$1*-1,BA4>0,AZ4>$D$2*-1,AX4/AW4>=3),"Very serious", AND(AY4<=$D$1*-1,BA4>0,AZ4<$D$2*-1,AX4/AW4>=3),"Very serious", AND(AY4>=$D$1,AZ4<0,BA4<$D$2,AX4/AW4>=3),"Very serious", AND(AY4>=$D$1,AZ4<0,BA4>$D$2,AX4/AW4>=3),"Very serious", AND(AY4>$D$1*-1,AY4<$D$1,AZ4>$D$1*-1,BA4<$D$1,AX4/AW4<3),"Not Serious", AND(AY4>$D$1*-1,AY4<$D$1,OR(AZ4<=$D$1*-1,BA4>=$D$1),AZ4>$D$2*-1,BA4<$D$2,AX4/AW4<3),"Serious", AND(AY4>$D$1*-1,AY4<$D$1,OR(AZ4<=$D$2*-1,BA4>=$D$2),AX4/AW4<3),"Very serious", AND(AY4>$D$1*-1,AY4<$D$1,AZ4>$D$1*-1,BA4<$D$1,AX4/AW4>=3),"Very serious", AND(AY4>$D$1*-1,AY4<$D$1,OR(AZ4<=$D$1*-1,BA4>=$D$1),AZ4>$D$2*-1,BA4<$D$2,AX4/AW4>=3),"Very serious", AND(AY4>$D$1*-1,AY4<$D$1,OR(AZ4<=$D$2*-1,BA4>=$D$2),AX4/AW4>=3),"Very serious"),"")) -> Extremely serious | BF4: =IF(OR(ISBLANK(BD4),AND(BE4<>"Not serious",BE4<>"Serious",BE4<>"Very serious",BE4<>"Extremely serious"),AS4="Assess imprecision",Q4="Assess imprecision"),"",IFERROR(IFS(BJ4-(2*COUNTIF(BD4,"Very serious")) - (2*COUNTIF(BE4,"Very serious"))- countif(BD4,"Serious") - countif(BE4,"Serious") - (3*countif(BE4,"Extremely serious"))=4,"HIGH", BJ4-(2*COUNTIF(BD4,"Very serious")) - (2*COUNTIF(BE4,"Very serious"))- countif(BD4,"Serious") - countif(BE4,"Serious") - (3*countif(BE4,"Extremely serious"))=3,"MODERATE", BJ4-(2*COUNTIF(BD4,"Very serious")) - (2*COUNTIF(BE4,"Very serious"))- countif(BD4,"Serious") - countif(BE4,"Serious") - (3*countif(BE4,"Extremely serious"))=2,"LOW", BJ4-(2*COUNTIF(BD4,"Very serious")) - (2*COUNTIF(BE4,"Very serious"))- countif(BD4,"Serious") - countif(BE4,"Serious") - (3*countif(BE4,"Extremely serious"))<=1,"VERY LOW"),"")) -> VERY LOW | BG4: =IFERROR(IFS(BD4="Serious","Finalize Direct & Indirect", BD4="Very serious","Finalize Direct & Indirect", BF4="HIGH","NMA",R4="HIGH","DIRECT",AT4="HIGH","INDIRECT",BF4="MODERATE","NMA",R4="MODERATE","DIRECT",AT4="MODERATE","INDIRECT",BF4="LOW","NMA",R4="LOW","DIRECT",AT4="LOW","INDIRECT",BF4="VERY LOW","NMA",R4="VERY LOW","DIRECT",AT4="VERY LOW","INDIRECT"),"") -> NMA | BH4: =IFS(BG4="NMA",BK4,BG4="Direct",BL4,BG4="Indirect",BM4) -> NO | BI4: =if(OR(AV4<=0.7,AV4>=1.3),iferror(if(AX4/AW4>=2.5,"Prelim Very serious",if(BA4-AZ4>200,"Prelim Very serious","Check manually")),if(isblank(AW4)=TRUE,"",if(AW4=0,"Prelim very serious","Error"))),"Check manually") -> Prelim Very serious | BJ4: =ifs(BC4="HIGH",4,BC4="MODERATE",3,BC4="LOW",2,BC4="VERY LOW",1) -> 4 | BK4: =IF(AND(AW4<1,AX4>1),"NO","YES") -> NO | BL4: =IF(AND(F4<1,G4>1),"NO","YES") -> NO | BM4: =IF(AND(U4<1,V4>1),"NO","YES") -> YES | BN4: =(iferror(ifs(L4="Serious","RoB, ",L4="Very Serious","RoBx2, "),"")&iferror(ifs(M4="Serious","Inconsistency, ",M4="Very Serious","Inconsistencyx2, "),"")&iferror(ifs(N4="Serious","Indirectness, ",N4="Very serious","Indirectnessx2, "),"")&iferror(ifs(O4="Serious","Publication bias, "),"")&iferror(ifs(CH4="Serious","Imprecision, ",CH4="Very Serious","Imprecisionx2, ",CH4="Extremely serious","Imprecisionx3, "),"")&iferror(ifs(CI4="Serious","Incoherence, ",CI4="Very Serious","Incoherencex2, ",CI4="NA","",CI4="Not serious",""),"")) -> Imprecisionx3, | BO4: =(IFERROR(IFS(BU4="RoB","RoB, ",BU4="RoBx2","RoBx2, ",BU4="NA",""),"")&IFERROR(IFS(BY4="RoB","Inconsistency, ",BY4="RoBx2","Inconsistencyx2, ",BY4="NA","")&IFERROR(IFS(CC4="RoB","Indirectness, ",CC4="RoBx2","Indirectnessx2, ",CC4="NA",""),"")&IFERROR(IFS(CG4="RoB","Publication bias, ",CG4="RoBx2","Publication biasx2, ",CG4="NA",""),"")&IFERROR(IFS(CH4="Serious","Imprecision, ",CH4="Very serious","Imprecisionx2, ",CH4="Extremely serious","Imprecisionx3, ",CH4="Not serious",""),"")&IFERROR(IFS(AQ4="Serious","Intransitivity, ",AQ4="Very serious","Intransitivityx2, ",AQ4="NA","",AQ4="Not serious",""),"")&IFERROR(IFS(CI4="Serious","Incoherence, ",CI4="Very serious","Incoherencex2, ",CI4="NA","",CI4="Not serious",""),""))) | BP4: =IFS(BB4="Direct",BN4,BB4="Indirect",BO4) -> Imprecisionx3, | BQ4: =IFERROR(LEFT(BP4, LEN(BP4)-2),"") -> Imprecisionx3 | BR4: =IFERROR(INDEX($A$4:$BF500,MATCH($AC4,$A$4:$A500,0),12),"NA") -> NA | BS4: =IFERROR(INDEX($A$4:$BF500,MATCH($AH4,$A$4:$A500,0),12),"NA") | BT4: =IFERROR(INDEX($A$4:$BF500,MATCH($AN4,$A$4:$A500,0),12),"NA") -> NA | BU4: =IFS(OR(BR4="Very Serious",BS4 = "Very Serious",BT4 = "Very Serious"), "RoBx2", OR(BR4="Serious",BS4 = "Serious",BT4 = "Serious"),"RoB", AND(BR4="NA",BS4 = "NA",BT4 = "NA"),"NA", OR(BR4="Not Serious",BS4 = "Not Serious",BT4 = "Not Serious"),"NA") -> #N/A | BV4: =IFERROR(INDEX($A$4:$BF500,MATCH($AC4,$A$4:$A500,0),13),"NA") -> NA | BW4: =IFERROR(INDEX($A$4:$BF500,MATCH($AH4,$A$4:$A500,0),13),"NA") | BX4: =IFERROR(INDEX($A$4:$BF500,MATCH($AN4,$A$4:$A500,0),13),"NA") -> NA | BY4: =IFS(OR(BV4="Very Serious",BW4 = "Very Serious",BX4 = "Very Serious"), "RoBx2", OR(BV4="Serious",BW4 = "Serious",BX4 = "Serious"),"RoB", AND(BV4="NA",BW4 = "NA",BX4 = "NA"),"NA", OR(BV4="Not Serious",BW4 = "Not Serious",BX4 = "Not Serious"),"NA") -> #N/A | BZ4: =IFERROR(INDEX($A$4:$BF500,MATCH($AC4,$A$4:$A500,0),14),"NA") -> NA | CA4: =IFERROR(INDEX($A$4:$BF500,MATCH($AH4,$A$4:$A500,0),14),"NA") | CB4: =IFERROR(INDEX($A$4:$BF500,MATCH($AN4,$A$4:$A500,0),14),"NA") -> NA | CC4: =IFS(OR(BZ4="Very Serious",CA4 = "Very Serious",CB4 = "Very Serious"), "RoBx2", OR(BZ4="Serious",CA4 = "Serious",CB4 = "Serious"),"RoB", AND(BZ4="NA",CA4 = "NA",CB4 = "NA"),"NA", OR(BZ4="Not Serious",CA4 = "Not Serious",CB4 = "Not Serious"),"NA") -> #N/A | CD4: =IFERROR(INDEX($A$4:$BF500,MATCH($AC4,$A$4:$A500,0),15),"NA") -> NA | CE4: =IFERROR(INDEX($A$4:$BF500,MATCH($AH4,$A$4:$A500,0),15),"NA") | CF4: =IFERROR(INDEX($A$4:$BF500,MATCH($AN4,$A$4:$A500,0),15),"NA") -> NA | CG4: =IFS(OR(CD4="Very Serious",CE4 = "Very Serious",CF4 = "Very Serious"), "RoBx2", OR(CD4="Serious",CE4 = "Serious",CF4 = "Serious"),"RoB", AND(CD4="NA",CE4 = "NA",CF4 = "NA"),"NA", OR(CD4="Not Serious",CE4 = "Not Serious",CF4 = "Not Serious"),"NA") -> #N/A | CH4: =IFS(BG4="NMA",BE4,BG4="Direct",Q4,BG4="Indirect",AS4) -> Extremely serious | CI4: =IFS(BG4="NMA",BD4,BG4="Direct","NA",BG4="Indirect","NA") -> Not serious | CJ4: =if(count(AV4:BA4)=6,if(abs(AY4)>=$D$1, if(AY4>0,if(OR(AZ4<0,BA4<0),if(and(BA4>$D$2,AZ4<$D$1),"2x, RD CIs very wide: Large harm to trivial effect or more","1x, RD CIs wide: crosses 0"),if(OR(AV4>=1.3,AV4<=0.7), if(and(count(AW4)=1,count(AX4)=1),if(round(AX4/AW4,2)>=2.5,"Wide OR CI: OIS not met","No serious imprecision"),"ERROR: check cell"),"No serious imprecision")),if(OR(AZ4>=0,BA4>=0),if(and(AZ4<(-1*$D$2),BA4>(-1*$D$1)),"2x, RD CIs very wide: Large benefit to trivial effect or more","1x, RD CIs wide: crosses 0"),if(OR(AV4>=1.3,AV4<=0.7), if(and(count(AW4)=1,count(AX4)=1),if(round(AX4/AW4,2)>=2.5,"Wide OR CI: OIS not met","No serious imprecision"),"ERROR: check cell"),"No serious imprecision"))),if(AY4>0,if(OR(AZ4<(-1*$D$1),BA4>$D$1),if(and(BA4>$D$2,AZ4<$D$1),"2x, RD CIs very wide: Large harm to trivial effect or more","1x, RD CIs wide: crosses MID"),if(OR(AV4>=1.3,AV4<=0.7), if(and(count(AW4)=1,count(AX4)=1),if(round(AX4/AW4,2)>=2.5,"Wide OR CI: OIS not met","No serious imprecision"),"ERROR: check cell"),"No serious imprecision")),if(OR(AZ4<=(-1*$D$1),BA4>=$D$1),if(and(AZ4<(-1*$D$2),BA4>(-1*$D$1)),"2x, RD CIs very wide: Large benefit to trivial effect or more","1x, RD CIs wide: crosses MID"),if(OR(AV4>=1.3,AV4<=0.7), if(and(count(AW4)=1,count(AX4)=1),if(round(AX4/AW4,2)>=2.5,"Wide OR CI: OIS not met","No serious imprecision"),"ERROR: check cell"),"No serious imprecision")))),"ERROR: check cell") -> 2x, RD CIs very wide: Large harm to trivial effect or more | CL4: =AND(OR(AX4/G4<0.9,AX4/G4>1.1),OR(AW4/F4<0.9,AW4/F4>1.1)) -> FALSE | CM4: =AND(OR(AX4/V4<0.9,AX4/V4>1.1),OR(AW4/U4<0.9,AW4/U4>1.1)) -> #VALUE! | CN4: =(4-(3*COUNTIF(P4,"VERY LOW"))-2*countif(P4,"LOW")-1*countif(P4,"MODERATE")) -> 4 | CO4: =(4-(3*COUNTIF(AR4,"VERY LOW"))-2*countif(AR4,"LOW")-1*countif(AR4,"MODERATE")) -> 4 | CP4: =IFS(C4=Preferences!B$13,B4,B4=Preferences!B$13,C4) -> A
A5: =IF(ISBLANK(B5),"",A4+1) -> 2 | B5: B | C5: Plac | E5: 0.52343627 | F5: 0.32876665 | G5: 0.83752584 | H5: -15.105893 | I5: -21.412973 | J5: -5.0975873 | L5: Serious | M5: Not serious | N5: Not serious | O5: Not serious | P5: =IF(OR(ISBLANK(L5),ISBLANK(M5),ISBLANK(N5),ISBLANK(O5)),"",if(OR(iserror(L5)=TRUE,iferror(L5="NA","NA")),"NA",ifs(4-(2*COUNTIF(L5:O5,"Very serious"))-countif(L5:O5,"Serious")=4,"HIGH",4-(2*COUNTIF(L5:O5,"Very serious"))-countif(L5:O5,"Serious")=3,"MODERATE",4-(2*COUNTIF(L5:O5,"Very serious"))-countif(L5:O5,"Serious")=2,"LOW",4-(2*COUNTIF(L5:O5,"Very serious"))-countif(L5:O5,"Serious")<=1,"VERY LOW"))) -> MODERATE | Q5: =IFERROR(IF(AND(Preferences!B$3="Manual",OR(AX5/AW5>G5/F5,BD5="Serious",BD5="Very serious")),"Assess imprecision",IFS(ISBLANK(E5),"",AND(Preferences!B$3="Automatic", G5/F5>=30),"Extremely serious",AND(H5<=$D$1*-1,J5<0,G5/F5<3),"Not serious",AND(H5<=$D$1*-1,J5<0,G5/F5>=3),"Very serious",AND(H5>=$D$1,I5>0,G5/F5<3),"Not serious",AND(H5>=$D$1,I5>0,G5/F5>=3),"Very serious",AND(H5<=$D$1*-1,J5>0,I5>$D$2*-1,G5/F5<3),"Serious", AND(H5<=$D$1*-1,J5>0,I5<$D$2*-1,G5/F5<3),"Very serious", AND(H5>=$D$1,I5<0,J5<$D$2,G5/F5<3),"Serious",AND(H5>=$D$1,I5<0,J5>$D$2,G5/F5<3),"Very serious", AND(H5<=$D$1*-1,J5>0,I5>$D$2*-1,G5/F5>=3),"Very serious", AND(H5<=$D$1*-1,J5>0,I5<$D$2*-1,G5/F5>=3),"Very serious", AND(H5>=$D$1,I5<0,J5<$D$2,G5/F5>=3),"Very serious", AND(H5>=$D$1,I5<0,J5>$D$2,G5/F5>=3),"Very serious", AND(H5>$D$1*-1,H5<$D$1,I5>$D$1*-1,J5<$D$1,G5/F5<3),"Not serious", AND(H5>$D$1*-1,H5<$D$1,OR(I5<=$D$1*-1,J5>=$D$1),I5>$D$2*-1,J5<$D$2,G5/F5<3),"Serious", AND(H5>$D$1*-1,H5<$D$1,OR(I5<=$D$2*-1,J5>=$D$2),G5/F5<3),"Very serious", AND(H5>$D$1*-1,H5<$D$1,I5>$D$1*-1,J5<$D$1,G5/F5>=3),"Very serious", AND(H5>$D$1*-1,H5<$D$1,OR(I5<=$D$1*-1,J5>=$D$1),I5>$D$2*-1,J5<$D$2,G5/F5>=3),"Very serious", AND(H5>$D$1*-1,H5<$D$1,OR(I5<=$D$2*-1,J5>=$D$2),G5/F5>=3),"Very serious")),"") -> Serious | R5: {=IFERROR(IFS(Q5="","",E5="NA","NA", AND(P5 = "HIGH",COUNTIF(Q5,"serious")>=1),"MODERATE", AND(P5 = "HIGH",COUNTIF(Q5,"Very serious")>=1),"LOW", AND(P5 = "HIGH",COUNTIF(Q5,"Extremely serious")>=1),"VERY LOW", AND(P5 = "HIGH",COUNTIF(Q5,"Not serious")>=1),P5, AND(P5 = "MODERATE",COUNTIF(Q5,"serious")>=1),"LOW", AND(P5 = "MODERATE",COUNTIF(Q5,"Very serious")>=1),"VERY LOW", AND(P5 = "MODERATE",COUNTIF(Q5,"Extremely serious")>=1),"VERY LOW", AND(P5 = "MODERATE",COUNTIF(Q5,"Not serious")>=1),P5, AND(P5 = "LOW",COUNTIF(Q5,"serious")>=1),"VERY LOW", AND(P5 = "LOW",COUNTIF(Q5,"Very serious")>=1),"VERY LOW", AND(P5 = "LOW",COUNTIF(Q5,"Extremely serious")>=1),"VERY LOW", AND(P5 = "LOW",COUNTIF(Q5,"Not serious")>=1),P5, P5 = "VERY LOW", P5),"")} -> LOW | T5: 0.35085325 | U5: 0.064485449 | V5: 1.8003028 | W5: -20.693323 | X5: -30.106068 | Y5: 24.34928 | Z5: {=INDEX($A$1:$C$500, MATCH(1,($B:$B=$B5)*($C:$C=$AB5),0),1)} -> 8 | AA5: {=INDEX($A$1:$C$500, MATCH(1,($B:$B=$AB5)*($C:$C=$B5),0),1)} -> #N/A | AB5: C | AC5: =IF(ISNUMBER(Z5),Z5,AA5) -> 8 | AD5: =IFERROR(INDEX($A$1:$R$500, MATCH(AC5,A:A,0),16),"") -> HIGH | AE5: {=INDEX($A$1:$C$500, MATCH(1,($B:$B=$AB5)*($C:$C=$AG5),0),1)} -> #N/A | AF5: {=INDEX($A$1:$C$500, MATCH(1,($B:$B=$AG5)*($C:$C=$AB5),0),1)} -> #N/A | AH5: =IF(ISNUMBER(AE5),AE5,AF5) -> #N/A | AI5: =IFERROR(INDEX($A$1:$R$500, MATCH(AH5,A:A,0),16),"") | AJ5: {=INDEX($A$1:$C$500, MATCH(1,($B:$B=$C5)*($C:$C=$AG5),0),1)} -> #N/A | AK5: {=INDEX($A$1:$C$500, MATCH(1,($B:$B=$AG5)*($C:$C=$C5),0),1)} -> #N/A | AL5: {=INDEX($A$1:$C$500, MATCH(1,($B:$B=$C5)*($C:$C=$AB5),0),1)} -> #N/A | AM5: {=INDEX($A$1:$C$500, MATCH(1,($B:$B=$AB5)*($C:$C=$C5),0),1)} -> 3 | AN5: {=IFS(ISNUMBER(AJ5),AJ5,ISNUMBER(AK5),AK5,ISNUMBER(AL5),AL5,ISNUMBER(AM5),AM5)} -> 3 | AO5: =IF(ISBLANK(AB5),"",INDEX($A$1:$R$500, MATCH(AN5,$A:$A,0),16)) -> MODERATE | AP5: =IF(ISBLANK(AB5),"",iferror(if(or(ifna(AD5,1)=1,ifna(AO5,1)=1),"#N/A",if(countif({AO5,AD5},"VERY LOW")>=1,"VERY LOW",if(countif({AO5,AD5},"LOW")>=1,"LOW",if(countif({AO5,AD5},"MODERATE")>=1,"MODERATE",if(countif({AO5,AD5},"HIGH")>=1,"HIGH","Check manually"))))),"#N/A")) -> MODERATE | AQ5: Not serious | AR5: =IF(OR(ISBLANK(AB5),ISBLANK(AQ5)),"",IFS(AND(AP5 = "HIGH",AQ5="Serious"),"MODERATE", AND(AP5 = "HIGH",AQ5="Not serious"),AP5, AND(AP5 = "MODERATE",AQ5="Serious"),"LOW", AND(AP5 = "MODERATE",AQ5 ="Not serious"),AP5, AND(AP5 = "LOW",AQ5="serious"),"VERY LOW", AND(AP5 = "LOW",AQ5="Not serious"),AP5, AND(AP5 = "HIGH",AQ5="Very serious"),"LOW", AND(AP5 = "MODERATE",AQ5="Very serious"),"VERY LOW", AND(AP5 = "LOW",AQ5="Very serious"),"VERY LOW", AP5 = "VERY LOW", AP5)) -> MODERATE | AS5: =IFERROR(IF(AND(Preferences!B$3="Manual",OR(AX5/AW5>V5/U5,BD5="Serious",BD5="Very serious")),"Assess imprecision",IFERROR(IFS(AND(Preferences!B$3="Automatic",V5/U5>=30),"Extremely serious",AND(W5<=$D$1*-1,Y5<0,V5/U5<3),"Not Serious",AND(W5<=$D$1*-1,Y5<0,V5/U5>=3),"Very serious",AND(W5>=$D$1,X5>0,V5/U5<3),"Not Serious",AND(W5>=$D$1,X5>0,V5/U5>=3),"Very serious",AND(W5<=$D$1*-1,Y5>0,X5>$D$2*-1,V5/U5<3),"Serious", AND(W5<=$D$1*-1,Y5>0,X5<$D$2*-1,V5/U5<3),"Very serious", AND(W5>=$D$1,X5<0,Y5<$D$2,V5/U5<3),"Serious",AND(W5>=$D$1,X5<0,Y5>$D$2,V5/U5<3),"Very serious", AND(W5<=$D$1*-1,Y5>0,X5>$D$2*-1,V5/U5>=3),"Very serious", AND(W5<=$D$1*-1,Y5>0,X5<$D$2*-1,V5/U5>=3),"Very serious", AND(W5>=$D$1,X5<0,Y5<$D$2,V5/U5>=3),"Very serious", AND(W5>=$D$1,X5<0,Y5>$D$2,V5/U5>=3),"Very serious", AND(W5>$D$1*-1,W5<$D$1,X5>$D$1*-1,Y5<$D$1,V5/U5<3),"Not Serious", AND(W5>$D$1*-1,W5<$D$1,OR(X5<=$D$1*-1,Y5>=$D$1),X5>$D$2*-1,Y5<$D$2,V5/U5<3),"Serious", AND(W5>$D$1*-1,W5<$D$1,OR(X5<=$D$2*-1,Y5>=$D$2),V5/U5<3),"Very serious", AND(W5>$D$1*-1,W5<$D$1,X5>$D$1*-1,Y5<$D$1,V5/U5>=3),"Very serious", AND(W5>$D$1*-1,W5<$D$1,OR(X5<=$D$1*-1,Y5>=$D$1),X5>$D$2*-1,Y5<$D$2,V5/U5>=3),"Very serious", AND(W5>$D$1*-1,W5<$D$1,OR(X5<=$D$2*-1,Y5>=$D$2),V5/U5>=3),"Very serious"),"")),"") -> Very serious | AT5: =IFERROR(IFS(T5="NA","NA",AS5="","",AS5="Assess imprecision","", AND(AR5 = "HIGH",COUNTIF(AS5,"serious")>=1),"MODERATE", AND(AR5 = "HIGH",COUNTIF(AS5,"Very serious")>=1),"LOW", AND(AR5 = "HIGH",COUNTIF(AS5,"Extremely serious")>=1),"VERY LOW", AND(AR5 = "HIGH",COUNTIF(AS5,"Not serious")>=1),AR5, AND(AR5 = "MODERATE",COUNTIF(AS5,"serious")>=1),"LOW", AND(AR5 = "MODERATE",COUNTIF(AS5,"Very serious")>=1),"VERY LOW", AND(AR5 = "MODERATE",COUNTIF(AS5,"Extremely serious")>=1),"VERY LOW", AND(AR5 = "MODERATE",COUNTIF(AS5,"Not serious")>=1),AR5, AND(AR5 = "LOW",COUNTIF(AS5,"serious")>=1),"VERY LOW", AND(AR5 = "LOW",COUNTIF(AS5,"Very serious")>=1),"VERY LOW", AND(AR5 = "LOW",COUNTIF(AS5,"Extremely serious")>=1),"VERY LOW", AND(AR5 = "LOW",COUNTIF(AS5,"Not serious")>=1),AR5, AR5 = "VERY LOW", AR5),"") -> VERY LOW | AV5: 0.49773374 | AW5: 0.31694089 | AX5: 0.77733024 | AY5: -15.534908 | AZ5: -21.724822 | BA5: -7.2300561 | BB5: =IF(Preferences!B$9="Manual","",IFS(ISBLANK(B5),"",AND(ISNUMBER(E5)=TRUE,ISNUMBER(T5)=FALSE),"Direct", AND(ISNUMBER(E5)=FALSE,ISNUMBER(T5)=TRUE),"Indirect", CN5=4,"Direct",AND(CL5=FALSE, CM5=TRUE,CN5-CO5>-1),"Direct", AND(CL5=FALSE,CM5=TRUE, CN5-CO5<0),"Check algorithm in appendix 2", AND(CL5=TRUE, CM5=FALSE,CN5-CO5>0),"Check algorithm in appendix 2", AND(CL5=TRUE, CM5=FALSE,CN5-CO5=0),"Indirect", AND(CL5=TRUE, CM5=FALSE,CN5-CO5<0),"Indirect", AND(CL5=FALSE,CM5=FALSE,CN5-CO5>-1),"Direct", AND(CL5=FALSE,CM5=FALSE,CN5-CO5<0),"Check algorithm in appendix 2", AND(CL5=TRUE,CM5=TRUE,CN5-CO5>-1),"Direct", AND(CL5=TRUE,CM5=TRUE,CN5-CO5<0),"Check algorithm in appendix 2")) -> Direct | BC5: =IFS(BB5="Direct",P5,BB5="Indirect",AR5,BB5="","",BB5="Check algorithm in appendix 2","") -> MODERATE | BD5: Not serious | BE5: =IF(Preferences!B$3="Manual","", IFERROR(IFS(AND(Preferences!B$3="Automatic",AX5/AW5>=30),"Extremely serious",AND(AY5<=$D$1*-1,BA5<0,AX5/AW5<3),"Not Serious",AND(AY5<=$D$1*-1,BA5<0,AX5/AW5>=3),"Very serious",AND(AY5>=$D$1,AZ5>0,AX5/AW5<3),"Not Serious",AND(AY5>=$D$1,AZ5>0,AX5/AW5>=3),"Very serious",AND(AY5<=$D$1*-1,BA5>0,AZ5>$D$2*-1,AX5/AW5<3),"Serious", AND(AY5<=$D$1*-1,BA5>0,AZ5<$D$2*-1,AX5/AW5<3),"Very serious", AND(AY5>=$D$1,AZ5<0,BA5<$D$2,AX5/AW5<3),"Serious",AND(AY5>=$D$1,AZ5<0,BA5>$D$2,AX5/AW5<3),"Very serious", AND(AY5<=$D$1*-1,BA5>0,AZ5>$D$2*-1,AX5/AW5>=3),"Very serious", AND(AY5<=$D$1*-1,BA5>0,AZ5<$D$2*-1,AX5/AW5>=3),"Very serious", AND(AY5>=$D$1,AZ5<0,BA5<$D$2,AX5/AW5>=3),"Very serious", AND(AY5>=$D$1,AZ5<0,BA5>$D$2,AX5/AW5>=3),"Very serious", AND(AY5>$D$1*-1,AY5<$D$1,AZ5>$D$1*-1,BA5<$D$1,AX5/AW5<3),"Not Serious", AND(AY5>$D$1*-1,AY5<$D$1,OR(AZ5<=$D$1*-1,BA5>=$D$1),AZ5>$D$2*-1,BA5<$D$2,AX5/AW5<3),"Serious", AND(AY5>$D$1*-1,AY5<$D$1,OR(AZ5<=$D$2*-1,BA5>=$D$2),AX5/AW5<3),"Very serious", AND(AY5>$D$1*-1,AY5<$D$1,AZ5>$D$1*-1,BA5<$D$1,AX5/AW5>=3),"Very serious", AND(AY5>$D$1*-1,AY5<$D$1,OR(AZ5<=$D$1*-1,BA5>=$D$1),AZ5>$D$2*-1,BA5<$D$2,AX5/AW5>=3),"Very serious", AND(AY5>$D$1*-1,AY5<$D$1,OR(AZ5<=$D$2*-1,BA5>=$D$2),AX5/AW5>=3),"Very serious"),"")) -> Serious | BF5: =IF(OR(ISBLANK(BD5),AND(BE5<>"Not serious",BE5<>"Serious",BE5<>"Very serious",BE5<>"Extremely serious"),AS5="Assess imprecision",Q5="Assess imprecision"),"",IFERROR(IFS(BJ5-(2*COUNTIF(BD5,"Very serious")) - (2*COUNTIF(BE5,"Very serious"))- countif(BD5,"Serious") - countif(BE5,"Serious") - (3*countif(BE5,"Extremely serious"))=4,"HIGH", BJ5-(2*COUNTIF(BD5,"Very serious")) - (2*COUNTIF(BE5,"Very serious"))- countif(BD5,"Serious") - countif(BE5,"Serious") - (3*countif(BE5,"Extremely serious"))=3,"MODERATE", BJ5-(2*COUNTIF(BD5,"Very serious")) - (2*COUNTIF(BE5,"Very serious"))- countif(BD5,"Serious") - countif(BE5,"Serious") - (3*countif(BE5,"Extremely serious"))=2,"LOW", BJ5-(2*COUNTIF(BD5,"Very serious")) - (2*COUNTIF(BE5,"Very serious"))- countif(BD5,"Serious") - countif(BE5,"Serious") - (3*countif(BE5,"Extremely serious"))<=1,"VERY LOW"),"")) -> LOW | BG5: =IFERROR(IFS(BF5="HIGH","NMA",R5="HIGH","DIRECT",AT5="HIGH","INDIRECT",BF5="MODERATE","NMA",R5="MODERATE","DIRECT",AT5="MODERATE","INDIRECT",BF5="LOW","NMA",R5="LOW","DIRECT",AT5="LOW","INDIRECT",BF5="VERY LOW","NMA",R5="VERY LOW","DIRECT",AT5="VERY LOW","INDIRECT"),"") -> NMA | BH5: =IFS(BG5="NMA",BK5,BG5="Direct",BL5,BG5="Indirect",BM5) -> YES | BI5: =if(OR(AV5<=0.7,AV5>=1.3),iferror(if(AX5/AW5>=2.5,"Prelim Very serious",if(BA5-AZ5>200,"Prelim Very serious","Check manually")),if(isblank(AW5)=TRUE,"",if(AW5=0,"Prelim very serious","Error"))),"Check manually") -> Check manually | BJ5: =ifs(BC5="HIGH",4,BC5="MODERATE",3,BC5="LOW",2,BC5="VERY LOW",1) -> 3 | BK5: =IF(AND(AW5<1,AX5>1),"NO","YES") -> YES | BL5: =IF(AND(F5<1,G5>1),"NO","YES") -> YES | BM5: =IF(AND(U5<1,V5>1),"NO","YES") -> NO | BN5: =(iferror(ifs(L5="Serious","RoB, ",L5="Very Serious","RoBx2, "),"")&iferror(ifs(M5="Serious","Inconsistency, ",M5="Very Serious","Inconsistencyx2, "),"")&iferror(ifs(N5="Serious","Indirectness, ",N5="Very serious","Indirectnessx2, "),"")&iferror(ifs(O5="Serious","Publication bias, "),"")&iferror(ifs(CH5="Serious","Imprecision, ",CH5="Very Serious","Imprecisionx2, ",CH5="Extremely serious","Imprecisionx3, "),"")&iferror(ifs(CI5="Serious","Incoherence, ",CI5="Very Serious","Incoherencex2, ",CI5="NA","",CI5="Not serious",""),"")) -> RoB, Imprecision, | BO5: =(IFERROR(IFS(BU5="RoB","RoB, ",BU5="RoBx2","RoBx2, ",BU5="NA",""),"")&IFERROR(IFS(BY5="RoB","Inconsistency, ",BY5="RoBx2","Inconsistencyx2, ",BY5="NA","")&IFERROR(IFS(CC5="RoB","Indirectness, ",CC5="RoBx2","Indirectnessx2, ",CC5="NA",""),"")&IFERROR(IFS(CG5="RoB","Publication bias, ",CG5="RoBx2","Publication biasx2, ",CG5="NA",""),"")&IFERROR(IFS(CH5="Serious","Imprecision, ",CH5="Very serious","Imprecisionx2, ",CH5="Extremely serious","Imprecisionx3, ",CH5="Not serious",""),"")&IFERROR(IFS(AQ5="Serious","Intransitivity, ",AQ5="Very serious","Intransitivityx2, ",AQ5="NA","",AQ5="Not serious",""),"")&IFERROR(IFS(CI5="Serious","Incoherence, ",CI5="Very serious","Incoherencex2, ",CI5="NA","",CI5="Not serious",""),""))) -> RoB, Imprecision, | BP5: =IFS(BB5="Direct",BN5,BB5="Indirect",BO5) -> RoB, Imprecision, | BQ5: =IFERROR(LEFT(BP5, LEN(BP5)-2),"") -> RoB, Imprecision | BR5: =IFERROR(INDEX($A$4:$BF501,MATCH($AC5,$A$4:$A501,0),12),"NA") -> Not serious | BS5: =IFERROR(INDEX($A$4:$BF501,MATCH($AH5,$A$4:$A501,0),12),"NA") -> NA | BT5: =IFERROR(INDEX($A$4:$BF501,MATCH($AN5,$A$4:$A501,0),12),"NA") -> Serious | BU5: =IFS(OR(BR5="Very Serious",BS5 = "Very Serious",BT5 = "Very Serious"), "RoBx2", OR(BR5="Serious",BS5 = "Serious",BT5 = "Serious"),"RoB", AND(BR5="NA",BS5 = "NA",BT5 = "NA"),"NA", OR(BR5="Not Serious",BS5 = "Not Serious",BT5 = "Not Serious"),"NA") -> RoB | BV5: =IFERROR(INDEX($A$4:$BF501,MATCH($AC5,$A$4:$A501,0),13),"NA") -> Not serious | BW5: =IFERROR(INDEX($A$4:$BF501,MATCH($AH5,$A$4:$A501,0),13),"NA") -> NA | BX5: =IFERROR(INDEX($A$4:$BF501,MATCH($AN5,$A$4:$A501,0),13),"NA") -> Not serious | BY5: =IFS(OR(BV5="Very Serious",BW5 = "Very Serious",BX5 = "Very Serious"), "RoBx2", OR(BV5="Serious",BW5 = "Serious",BX5 = "Serious"),"RoB", AND(BV5="NA",BW5 = "NA",BX5 = "NA"),"NA", OR(BV5="Not Serious",BW5 = "Not Serious",BX5 = "Not Serious"),"NA") -> NA | BZ5: =IFERROR(INDEX($A$4:$BF501,MATCH($AC5,$A$4:$A501,0),14),"NA") -> Not serious | CA5: =IFERROR(INDEX($A$4:$BF501,MATCH($AH5,$A$4:$A501,0),14),"NA") -> NA | CB5: =IFERROR(INDEX($A$4:$BF501,MATCH($AN5,$A$4:$A501,0),14),"NA") -> Not serious | CC5: =IFS(OR(BZ5="Very Serious",CA5 = "Very Serious",CB5 = "Very Serious"), "RoBx2", OR(BZ5="Serious",CA5 = "Serious",CB5 = "Serious"),"RoB", AND(BZ5="NA",CA5 = "NA",CB5 = "NA"),"NA", OR(BZ5="Not Serious",CA5 = "Not Serious",CB5 = "Not Serious"),"NA") -> NA | CD5: =IFERROR(INDEX($A$4:$BF501,MATCH($AC5,$A$4:$A501,0),15),"NA") -> Not serious | CE5: =IFERROR(INDEX($A$4:$BF501,MATCH($AH5,$A$4:$A501,0),15),"NA") -> NA | CF5: =IFERROR(INDEX($A$4:$BF501,MATCH($AN5,$A$4:$A501,0),15),"NA") -> Not serious | CG5: =IFS(OR(CD5="Very Serious",CE5 = "Very Serious",CF5 = "Very Serious"), "RoBx2", OR(CD5="Serious",CE5 = "Serious",CF5 = "Serious"),"RoB", AND(CD5="NA",CE5 = "NA",CF5 = "NA"),"NA", OR(CD5="Not Serious",CE5 = "Not Serious",CF5 = "Not Serious"),"NA") -> NA | CH5: =IFS(BG5="NMA",BE5,BG5="Direct",Q5,BG5="Indirect",AS5) -> Serious | CI5: =IFS(BG5="NMA",BD5,BG5="Direct","NA",BG5="Indirect","NA") -> Not serious | CJ5: =if(count(AV5:BA5)=6,if(abs(AY5)>=$D$1, if(AY5>0,if(OR(AZ5<0,BA5<0),if(and(BA5>$D$2,AZ5<$D$1),"2x, RD CIs very wide: Large harm to trivial effect or more","1x, RD CIs wide: crosses 0"),if(OR(AV5>=1.3,AV5<=0.7), if(and(count(AW5)=1,count(AX5)=1),if(round(AX5/AW5,2)>=2.5,"Wide OR CI: OIS not met","No serious imprecision"),"ERROR: check cell"),"No serious imprecision")),if(OR(AZ5>=0,BA5>=0),if(and(AZ5<(-1*$D$2),BA5>(-1*$D$1)),"2x, RD CIs very wide: Large benefit to trivial effect or more","1x, RD CIs wide: crosses 0"),if(OR(AV5>=1.3,AV5<=0.7), if(and(count(AW5)=1,count(AX5)=1),if(round(AX5/AW5,2)>=2.5,"Wide OR CI: OIS not met","No serious imprecision"),"ERROR: check cell"),"No serious imprecision"))),if(AY5>0,if(OR(AZ5<(-1*$D$1),BA5>$D$1),if(and(BA5>$D$2,AZ5<$D$1),"2x, RD CIs very wide: Large harm to trivial effect or more","1x, RD CIs wide: crosses MID"),if(OR(AV5>=1.3,AV5<=0.7), if(and(count(AW5)=1,count(AX5)=1),if(round(AX5/AW5,2)>=2.5,"Wide OR CI: OIS not met","No serious imprecision"),"ERROR: check cell"),"No serious imprecision")),if(OR(AZ5<=(-1*$D$1),BA5>=$D$1),if(and(AZ5<(-1*$D$2),BA5>(-1*$D$1)),"2x, RD CIs very wide: Large benefit to trivial effect or more","1x, RD CIs wide: crosses MID"),if(OR(AV5>=1.3,AV5<=0.7), if(and(count(AW5)=1,count(AX5)=1),if(round(AX5/AW5,2)>=2.5,"Wide OR CI: OIS not met","No serious imprecision"),"ERROR: check cell"),"No serious imprecision")))),"ERROR: check cell") -> 1x, RD CIs wide: crosses MID | CL5: =AND(OR(AX5/G5<0.9,AX5/G5>1.1),OR(AW5/F5<0.9,AW5/F5>1.1)) -> FALSE | CM5: =AND(OR(AX5/V5<0.9,AX5/V5>1.1),OR(AW5/U5<0.9,AW5/U5>1.1)) -> TRUE | CN5: =(4-(3*COUNTIF(P5,"VERY LOW"))-2*countif(P5,"LOW")-1*countif(P5,"MODERATE")) -> 3 | CO5: =(4-(3*COUNTIF(AR5,"VERY LOW"))-2*countif(AR5,"LOW")-1*countif(AR5,"MODERATE")) -> 3 | CP5: =IFS(C5=Preferences!B$13,B5,B5=Preferences!B$13,C5) -> B
A6: =IF(ISBLANK(B6),"",A5+1) -> 3 | B6: C | C6: Plac | E6: 1.1666667 | F6: 0.22545893 | G6: 6.0368298 | H6: 5.1739162 | I6: -24.793017 | J6: 135.23387 | L6: Serious | M6: Not serious | N6: Not serious | O6: Not serious | P6: =IF(OR(ISBLANK(L6),ISBLANK(M6),ISBLANK(N6),ISBLANK(O6)),"",if(OR(iserror(L6)=TRUE,iferror(L6="NA","NA")),"NA",ifs(4-(2*COUNTIF(L6:O6,"Very serious"))-countif(L6:O6,"Serious")=4,"HIGH",4-(2*COUNTIF(L6:O6,"Very serious"))-countif(L6:O6,"Serious")=3,"MODERATE",4-(2*COUNTIF(L6:O6,"Very serious"))-countif(L6:O6,"Serious")=2,"LOW",4-(2*COUNTIF(L6:O6,"Very serious"))-countif(L6:O6,"Serious")<=1,"VERY LOW"))) -> MODERATE | Q6: =IFERROR(IF(AND(Preferences!B$3="Manual",OR(AX6/AW6>G6/F6,BD6="Serious",BD6="Very serious")),"Assess imprecision",IFS(ISBLANK(E6),"",AND(Preferences!B$3="Automatic", G6/F6>=30),"Extremely serious",AND(H6<=$D$1*-1,J6<0,G6/F6<3),"Not serious",AND(H6<=$D$1*-1,J6<0,G6/F6>=3),"Very serious",AND(H6>=$D$1,I6>0,G6/F6<3),"Not serious",AND(H6>=$D$1,I6>0,G6/F6>=3),"Very serious",AND(H6<=$D$1*-1,J6>0,I6>$D$2*-1,G6/F6<3),"Serious", AND(H6<=$D$1*-1,J6>0,I6<$D$2*-1,G6/F6<3),"Very serious", AND(H6>=$D$1,I6<0,J6<$D$2,G6/F6<3),"Serious",AND(H6>=$D$1,I6<0,J6>$D$2,G6/F6<3),"Very serious", AND(H6<=$D$1*-1,J6>0,I6>$D$2*-1,G6/F6>=3),"Very serious", AND(H6<=$D$1*-1,J6>0,I6<$D$2*-1,G6/F6>=3),"Very serious", AND(H6>=$D$1,I6<0,J6<$D$2,G6/F6>=3),"Very serious", AND(H6>=$D$1,I6<0,J6>$D$2,G6/F6>=3),"Very serious", AND(H6>$D$1*-1,H6<$D$1,I6>$D$1*-1,J6<$D$1,G6/F6<3),"Not serious", AND(H6>$D$1*-1,H6<$D$1,OR(I6<=$D$1*-1,J6>=$D$1),I6>$D$2*-1,J6<$D$2,G6/F6<3),"Serious", AND(H6>$D$1*-1,H6<$D$1,OR(I6<=$D$2*-1,J6>=$D$2),G6/F6<3),"Very serious", AND(H6>$D$1*-1,H6<$D$1,I6>$D$1*-1,J6<$D$1,G6/F6>=3),"Very serious", AND(H6>$D$1*-1,H6<$D$1,OR(I6<=$D$1*-1,J6>=$D$1),I6>$D$2*-1,J6<$D$2,G6/F6>=3),"Very serious", AND(H6>$D$1*-1,H6<$D$1,OR(I6<=$D$2*-1,J6>=$D$2),G6/F6>=3),"Very serious")),"") -> Very serious | R6: =IFERROR(IFS(E6="NA","NA", AND(P6 = "HIGH",COUNTIF(Q6,"serious")>=1),"MODERATE", AND(P6 = "HIGH",COUNTIF(Q6,"Very serious")>=1),"LOW", AND(P6 = "HIGH",COUNTIF(Q6,"Extremely serious")>=1),"VERY LOW", AND(P6 = "HIGH",COUNTIF(Q6,"Not serious")>=1),P6, AND(P6 = "MODERATE",COUNTIF(Q6,"serious")>=1),"LOW", AND(P6 = "MODERATE",COUNTIF(Q6,"Very serious")>=1),"VERY LOW", AND(P6 = "MODERATE",COUNTIF(Q6,"Extremely serious")>=1),"VERY LOW", AND(P6 = "MODERATE",COUNTIF(Q6,"Not serious")>=1),P6, AND(P6 = "LOW",COUNTIF(Q6,"serious")>=1),"VERY LOW", AND(P6 = "LOW",COUNTIF(Q6,"Very serious")>=1),"VERY LOW", AND(P6 = "LOW",COUNTIF(Q6,"Extremely serious")>=1),"VERY LOW", AND(P6 = "LOW",COUNTIF(Q6,"Not serious")>=1),P6, P6 = "VERY LOW", P6),"") -> VERY LOW | T6: 1.7210996 | U6: 0.63078166 | V6: 5.3219865 | W6: 21.994281 | X6: -11.662305 | Y6: 118.38898 | Z6: {=INDEX($A$1:$C$500, MATCH(1,($B:$B=$B6)*($C:$C=$AB6),0),1)} -> #N/A | AA6: {=INDEX($A$1:$C$500, MATCH(1,($B:$B=$AB6)*($C:$C=$B6),0),1)} -> 8 | AB6: B | AC6: =IF(ISNUMBER(Z6),Z6,AA6) -> 8 | AD6: =IFERROR(INDEX($A$1:$R$500, MATCH(AC6,A:A,0),16),"") -> HIGH | AE6: {=INDEX($A$1:$C$500, MATCH(1,($B:$B=$AB6)*($C:$C=$AG6),0),1)} -> #N/A | AF6: {=INDEX($A$1:$C$500, MATCH(1,($B:$B=$AG6)*($C:$C=$AB6),0),1)} -> #N/A | AH6: =IF(ISNUMBER(AE6),AE6,AF6) -> #N/A | AI6: =IFERROR(INDEX($A$1:$R$500, MATCH(AH6,A:A,0),16),"") | AJ6: {=INDEX($A$1:$C$500, MATCH(1,($B:$B=$C6)*($C:$C=$AG6),0),1)} -> #N/A | AK6: {=INDEX($A$1:$C$500, MATCH(1,($B:$B=$AG6)*($C:$C=$C6),0),1)} -> #N/A | AL6: {=INDEX($A$1:$C$500, MATCH(1,($B:$B=$C6)*($C:$C=$AB6),0),1)} -> #N/A | AM6: {=INDEX($A$1:$C$500, MATCH(1,($B:$B=$AB6)*($C:$C=$C6),0),1)} -> 2 | AN6: {=IFS(ISNUMBER(AJ6),AJ6,ISNUMBER(AK6),AK6,ISNUMBER(AL6),AL6,ISNUMBER(AM6),AM6)} -> 2 | AO6: =IF(ISBLANK(AB6),"",INDEX($A$1:$R$500, MATCH(AN6,$A:$A,0),16)) -> MODERATE | AP6: =IF(ISBLANK(AB6),"",iferror(if(or(ifna(AD6,1)=1,ifna(AO6,1)=1),"#N/A",if(countif({AO6,AD6},"VERY LOW")>=1,"VERY LOW",if(countif({AO6,AD6},"LOW")>=1,"LOW",if(countif({AO6,AD6},"MODERATE")>=1,"MODERATE",if(countif({AO6,AD6},"HIGH")>=1,"HIGH","Check manually"))))),"#N/A")) -> MODERATE | AQ6: Not serious | AR6: =IF(OR(ISBLANK(AB6),ISBLANK(AQ6)),"",IFS(AND(AP6 = "HIGH",AQ6="Serious"),"MODERATE", AND(AP6 = "HIGH",AQ6="Not serious"),AP6, AND(AP6 = "MODERATE",AQ6="Serious"),"LOW", AND(AP6 = "MODERATE",AQ6 ="Not serious"),AP6, AND(AP6 = "LOW",AQ6="serious"),"VERY LOW", AND(AP6 = "LOW",AQ6="Not serious"),AP6, AND(AP6 = "HIGH",AQ6="Very serious"),"LOW", AND(AP6 = "MODERATE",AQ6="Very serious"),"VERY LOW", AND(AP6 = "LOW",AQ6="Very serious"),"VERY LOW", AP6 = "VERY LOW", AP6)) -> MODERATE | AS6: =IFERROR(IF(AND(Preferences!B$3="Manual",OR(AX6/AW6>V6/U6,BD6="Serious",BD6="Very serious")),"Assess imprecision",IFERROR(IFS(AND(Preferences!B$3="Automatic",V6/U6>=30),"Extremely serious",AND(W6<=$D$1*-1,Y6<0,V6/U6<3),"Not Serious",AND(W6<=$D$1*-1,Y6<0,V6/U6>=3),"Very serious",AND(W6>=$D$1,X6>0,V6/U6<3),"Not Serious",AND(W6>=$D$1,X6>0,V6/U6>=3),"Very serious",AND(W6<=$D$1*-1,Y6>0,X6>$D$2*-1,V6/U6<3),"Serious", AND(W6<=$D$1*-1,Y6>0,X6<$D$2*-1,V6/U6<3),"Very serious", AND(W6>=$D$1,X6<0,Y6<$D$2,V6/U6<3),"Serious",AND(W6>=$D$1,X6<0,Y6>$D$2,V6/U6<3),"Very serious", AND(W6<=$D$1*-1,Y6>0,X6>$D$2*-1,V6/U6>=3),"Very serious", AND(W6<=$D$1*-1,Y6>0,X6<$D$2*-1,V6/U6>=3),"Very serious", AND(W6>=$D$1,X6<0,Y6<$D$2,V6/U6>=3),"Very serious", AND(W6>=$D$1,X6<0,Y6>$D$2,V6/U6>=3),"Very serious", AND(W6>$D$1*-1,W6<$D$1,X6>$D$1*-1,Y6<$D$1,V6/U6<3),"Not Serious", AND(W6>$D$1*-1,W6<$D$1,OR(X6<=$D$1*-1,Y6>=$D$1),X6>$D$2*-1,Y6<$D$2,V6/U6<3),"Serious", AND(W6>$D$1*-1,W6<$D$1,OR(X6<=$D$2*-1,Y6>=$D$2),V6/U6<3),"Very serious", AND(W6>$D$1*-1,W6<$D$1,X6>$D$1*-1,Y6<$D$1,V6/U6>=3),"Very serious", AND(W6>$D$1*-1,W6<$D$1,OR(X6<=$D$1*-1,Y6>=$D$1),X6>$D$2*-1,Y6<$D$2,V6/U6>=3),"Very serious", AND(W6>$D$1*-1,W6<$D$1,OR(X6<=$D$2*-1,Y6>=$D$2),V6/U6>=3),"Very serious"),"")),"") -> Very serious | AT6: =IFERROR(IFS(T6="NA","NA",AS6="","",AS6="Assess imprecision","", AND(AR6 = "HIGH",COUNTIF(AS6,"serious")>=1),"MODERATE", AND(AR6 = "HIGH",COUNTIF(AS6,"Very serious")>=1),"LOW", AND(AR6 = "HIGH",COUNTIF(AS6,"Extremely serious")>=1),"VERY LOW", AND(AR6 = "HIGH",COUNTIF(AS6,"Not serious")>=1),AR6, AND(AR6 = "MODERATE",COUNTIF(AS6,"serious")>=1),"LOW", AND(AR6 = "MODERATE",COUNTIF(AS6,"Very serious")>=1),"VERY LOW", AND(AR6 = "MODERATE",COUNTIF(AS6,"Extremely serious")>=1),"VERY LOW", AND(AR6 = "MODERATE",COUNTIF(AS6,"Not serious")>=1),AR6, AND(AR6 = "LOW",COUNTIF(AS6,"serious")>=1),"VERY LOW", AND(AR6 = "LOW",COUNTIF(AS6,"Very serious")>=1),"VERY LOW", AND(AR6 = "LOW",COUNTIF(AS6,"Extremely serious")>=1),"VERY LOW", AND(AR6 = "LOW",COUNTIF(AS6,"Not serious")>=1),AR6, AR6 = "VERY LOW", AR6),"") -> VERY LOW | AV6: 1.4907361 | AW6: 0.68663666 | AX6: 3.4081172 | AY6: 18.544654 | AZ6: -9.8264429 | BA6: 67.392375 | BB6: =IF(Preferences!B$9="Manual","",IFS(ISBLANK(B6),"",AND(ISNUMBER(E6)=TRUE,ISNUMBER(T6)=FALSE),"Direct", AND(ISNUMBER(E6)=FALSE,ISNUMBER(T6)=TRUE),"Indirect", CN6=4,"Direct",AND(CL6=FALSE, CM6=TRUE,CN6-CO6>-1),"Direct", AND(CL6=FALSE,CM6=TRUE, CN6-CO6<0),"Check algorithm in appendix 2", AND(CL6=TRUE, CM6=FALSE,CN6-CO6>0),"Check algorithm in appendix 2", AND(CL6=TRUE, CM6=FALSE,CN6-CO6=0),"Indirect", AND(CL6=TRUE, CM6=FALSE,CN6-CO6<0),"Indirect", AND(CL6=FALSE,CM6=FALSE,CN6-CO6>-1),"Direct", AND(CL6=FALSE,CM6=FALSE,CN6-CO6<0),"Check algorithm in appendix 2", AND(CL6=TRUE,CM6=TRUE,CN6-CO6>-1),"Direct", AND(CL6=TRUE,CM6=TRUE,CN6-CO6<0),"Check algorithm in appendix 2")) -> Indirect | BC6: =IFS(BB6="Direct",P6,BB6="Indirect",AR6,BB6="","",BB6="Check algorithm in appendix 2","") -> MODERATE | BD6: Not serious | BE6: =IF(Preferences!B$3="Manual","", IFERROR(IFS(AND(Preferences!B$3="Automatic",AX6/AW6>=30),"Extremely serious",AND(AY6<=$D$1*-1,BA6<0,AX6/AW6<3),"Not Serious",AND(AY6<=$D$1*-1,BA6<0,AX6/AW6>=3),"Very serious",AND(AY6>=$D$1,AZ6>0,AX6/AW6<3),"Not Serious",AND(AY6>=$D$1,AZ6>0,AX6/AW6>=3),"Very serious",AND(AY6<=$D$1*-1,BA6>0,AZ6>$D$2*-1,AX6/AW6<3),"Serious", AND(AY6<=$D$1*-1,BA6>0,AZ6<$D$2*-1,AX6/AW6<3),"Very serious", AND(AY6>=$D$1,AZ6<0,BA6<$D$2,AX6/AW6<3),"Serious",AND(AY6>=$D$1,AZ6<0,BA6>$D$2,AX6/AW6<3),"Very serious", AND(AY6<=$D$1*-1,BA6>0,AZ6>$D$2*-1,AX6/AW6>=3),"Very serious", AND(AY6<=$D$1*-1,BA6>0,AZ6<$D$2*-1,AX6/AW6>=3),"Very serious", AND(AY6>=$D$1,AZ6<0,BA6<$D$2,AX6/AW6>=3),"Very serious", AND(AY6>=$D$1,AZ6<0,BA6>$D$2,AX6/AW6>=3),"Very serious", AND(AY6>$D$1*-1,AY6<$D$1,AZ6>$D$1*-1,BA6<$D$1,AX6/AW6<3),"Not Serious", AND(AY6>$D$1*-1,AY6<$D$1,OR(AZ6<=$D$1*-1,BA6>=$D$1),AZ6>$D$2*-1,BA6<$D$2,AX6/AW6<3),"Serious", AND(AY6>$D$1*-1,AY6<$D$1,OR(AZ6<=$D$2*-1,BA6>=$D$2),AX6/AW6<3),"Very serious", AND(AY6>$D$1*-1,AY6<$D$1,AZ6>$D$1*-1,BA6<$D$1,AX6/AW6>=3),"Very serious", AND(AY6>$D$1*-1,AY6<$D$1,OR(AZ6<=$D$1*-1,BA6>=$D$1),AZ6>$D$2*-1,BA6<$D$2,AX6/AW6>=3),"Very serious", AND(AY6>$D$1*-1,AY6<$D$1,OR(AZ6<=$D$2*-1,BA6>=$D$2),AX6/AW6>=3),"Very serious"),"")) -> Very serious | BF6: =IF(OR(ISBLANK(BD6),AND(BE6<>"Not serious",BE6<>"Serious",BE6<>"Very serious",BE6<>"Extremely serious"),AS6="Assess imprecision",Q6="Assess imprecision"),"",IFERROR(IFS(BJ6-(2*COUNTIF(BD6,"Very serious")) - (2*COUNTIF(BE6,"Very serious"))- countif(BD6,"Serious") - countif(BE6,"Serious") - (3*countif(BE6,"Extremely serious"))=4,"HIGH", BJ6-(2*COUNTIF(BD6,"Very serious")) - (2*COUNTIF(BE6,"Very serious"))- countif(BD6,"Serious") - countif(BE6,"Serious") - (3*countif(BE6,"Extremely serious"))=3,"MODERATE", BJ6-(2*COUNTIF(BD6,"Very serious")) - (2*COUNTIF(BE6,"Very serious"))- countif(BD6,"Serious") - countif(BE6,"Serious") - (3*countif(BE6,"Extremely serious"))=2,"LOW", BJ6-(2*COUNTIF(BD6,"Very serious")) - (2*COUNTIF(BE6,"Very serious"))- countif(BD6,"Serious") - countif(BE6,"Serious") - (3*countif(BE6,"Extremely serious"))<=1,"VERY LOW"),"")) -> VERY LOW | BG6: =IFERROR(IFS(BF6="HIGH","NMA",R6="HIGH","DIRECT",AT6="HIGH","INDIRECT",BF6="MODERATE","NMA",R6="MODERATE","DIRECT",AT6="MODERATE","INDIRECT",BF6="LOW","NMA",R6="LOW","DIRECT",AT6="LOW","INDIRECT",BF6="VERY LOW","NMA",R6="VERY LOW","DIRECT",AT6="VERY LOW","INDIRECT"),"") -> NMA | BH6: =IFS(BG6="NMA",BK6,BG6="Direct",BL6,BG6="Indirect",BM6) -> NO | BI6: =if(OR(AV6<=0.7,AV6>=1.3),iferror(if(AX6/AW6>=2.5,"Prelim Very serious",if(BA6-AZ6>200,"Prelim Very serious","Check manually")),if(isblank(AW6)=TRUE,"",if(AW6=0,"Prelim very serious","Error"))),"Check manually") -> Prelim Very serious | BJ6: =ifs(BC6="HIGH",4,BC6="MODERATE",3,BC6="LOW",2,BC6="VERY LOW",1) -> 3 | BK6: =IF(AND(AW6<1,AX6>1),"NO","YES") -> NO | BL6: =IF(AND(F6<1,G6>1),"NO","YES") -> NO | BM6: =IF(AND(U6<1,V6>1),"NO","YES") -> NO | BN6: =(iferror(ifs(L6="Serious","RoB, ",L6="Very Serious","RoBx2, "),"")&iferror(ifs(M6="Serious","Inconsistency, ",M6="Very Serious","Inconsistencyx2, "),"")&iferror(ifs(N6="Serious","Indirectness, ",N6="Very serious","Indirectnessx2, "),"")&iferror(ifs(O6="Serious","Publication bias, "),"")&iferror(ifs(CH6="Serious","Imprecision, ",CH6="Very Serious","Imprecisionx2, ",CH6="Extremely serious","Imprecisionx3, "),"")&iferror(ifs(CI6="Serious","Incoherence, ",CI6="Very Serious","Incoherencex2, ",CI6="NA","",CI6="Not serious",""),"")) -> RoB, Imprecisionx2, | BO6: =(IFERROR(IFS(BU6="RoB","RoB, ",BU6="RoBx2","RoBx2, ",BU6="NA",""),"")&IFERROR(IFS(BY6="RoB","Inconsistency, ",BY6="RoBx2","Inconsistencyx2, ",BY6="NA","")&IFERROR(IFS(CC6="RoB","Indirectness, ",CC6="RoBx2","Indirectnessx2, ",CC6="NA",""),"")&IFERROR(IFS(CG6="RoB","Publication bias, ",CG6="RoBx2","Publication biasx2, ",CG6="NA",""),"")&IFERROR(IFS(CH6="Serious","Imprecision, ",CH6="Very serious","Imprecisionx2, ",CH6="Extremely serious","Imprecisionx3, ",CH6="Not serious",""),"")&IFERROR(IFS(AQ6="Serious","Intransitivity, ",AQ6="Very serious","Intransitivityx2, ",AQ6="NA","",AQ6="Not serious",""),"")&IFERROR(IFS(CI6="Serious","Incoherence, ",CI6="Very serious","Incoherencex2, ",CI6="NA","",CI6="Not serious",""),""))) -> RoB, Imprecisionx2, | BP6: =IFS(BB6="Direct",BN6,BB6="Indirect",BO6) -> RoB, Imprecisionx2, | BQ6: =IFERROR(LEFT(BP6, LEN(BP6)-2),"") -> RoB, Imprecisionx2 | BR6: =IFERROR(INDEX($A$4:$BF502,MATCH($AC6,$A$4:$A502,0),12),"NA") -> Not serious | BS6: =IFERROR(INDEX($A$4:$BF502,MATCH($AH6,$A$4:$A502,0),12),"NA") -> NA | BT6: =IFERROR(INDEX($A$4:$BF502,MATCH($AN6,$A$4:$A502,0),12),"NA") -> Serious | BU6: =IFS(OR(BR6="Very Serious",BS6 = "Very Serious",BT6 = "Very Serious"), "RoBx2", OR(BR6="Serious",BS6 = "Serious",BT6 = "Serious"),"RoB", AND(BR6="NA",BS6 = "NA",BT6 = "NA"),"NA", OR(BR6="Not Serious",BS6 = "Not Serious",BT6 = "Not Serious"),"NA") -> RoB | BV6: =IFERROR(INDEX($A$4:$BF502,MATCH($AC6,$A$4:$A502,0),13),"NA") -> Not serious | BW6: =IFERROR(INDEX($A$4:$BF502,MATCH($AH6,$A$4:$A502,0),13),"NA") -> NA | BX6: =IFERROR(INDEX($A$4:$BF502,MATCH($AN6,$A$4:$A502,0),13),"NA") -> Not serious | BY6: =IFS(OR(BV6="Very Serious",BW6 = "Very Serious",BX6 = "Very Serious"), "RoBx2", OR(BV6="Serious",BW6 = "Serious",BX6 = "Serious"),"RoB", AND(BV6="NA",BW6 = "NA",BX6 = "NA"),"NA", OR(BV6="Not Serious",BW6 = "Not Serious",BX6 = "Not Serious"),"NA") -> NA | BZ6: =IFERROR(INDEX($A$4:$BF502,MATCH($AC6,$A$4:$A502,0),14),"NA") -> Not serious | CA6: =IFERROR(INDEX($A$4:$BF502,MATCH($AH6,$A$4:$A502,0),14),"NA") -> NA | CB6: =IFERROR(INDEX($A$4:$BF502,MATCH($AN6,$A$4:$A502,0),14),"NA") -> Not serious | CC6: =IFS(OR(BZ6="Very Serious",CA6 = "Very Serious",CB6 = "Very Serious"), "RoBx2", OR(BZ6="Serious",CA6 = "Serious",CB6 = "Serious"),"RoB", AND(BZ6="NA",CA6 = "NA",CB6 = "NA"),"NA", OR(BZ6="Not Serious",CA6 = "Not Serious",CB6 = "Not Serious"),"NA") -> NA | CD6: =IFERROR(INDEX($A$4:$BF502,MATCH($AC6,$A$4:$A502,0),15),"NA") -> Not serious | CE6: =IFERROR(INDEX($A$4:$BF502,MATCH($AH6,$A$4:$A502,0),15),"NA") -> NA | CF6: =IFERROR(INDEX($A$4:$BF502,MATCH($AN6,$A$4:$A502,0),15),"NA") -> Not serious | CG6: =IFS(OR(CD6="Very Serious",CE6 = "Very Serious",CF6 = "Very Serious"), "RoBx2", OR(CD6="Serious",CE6 = "Serious",CF6 = "Serious"),"RoB", AND(CD6="NA",CE6 = "NA",CF6 = "NA"),"NA", OR(CD6="Not Serious",CE6 = "Not Serious",CF6 = "Not Serious"),"NA") -> NA | CH6: =IFS(BG6="NMA",BE6,BG6="Direct",Q6,BG6="Indirect",AS6) -> Very serious | CI6: =IFS(BG6="NMA",BD6,BG6="Direct","NA",BG6="Indirect","NA") -> Not serious | CJ6: =if(count(AV6:BA6)=6,if(abs(AY6)>=$D$1, if(AY6>0,if(OR(AZ6<0,BA6<0),if(and(BA6>$D$2,AZ6<$D$1),"2x, RD CIs very wide: Large harm to trivial effect or more","1x, RD CIs wide: crosses 0"),if(OR(AV6>=1.3,AV6<=0.7), if(and(count(AW6)=1,count(AX6)=1),if(round(AX6/AW6,2)>=2.5,"Wide OR CI: OIS not met","No serious imprecision"),"ERROR: check cell"),"No serious imprecision")),if(OR(AZ6>=0,BA6>=0),if(and(AZ6<(-1*$D$2),BA6>(-1*$D$1)),"2x, RD CIs very wide: Large benefit to trivial effect or more","1x, RD CIs wide: crosses 0"),if(OR(AV6>=1.3,AV6<=0.7), if(and(count(AW6)=1,count(AX6)=1),if(round(AX6/AW6,2)>=2.5,"Wide OR CI: OIS not met","No serious imprecision"),"ERROR: check cell"),"No serious imprecision"))),if(AY6>0,if(OR(AZ6<(-1*$D$1),BA6>$D$1),if(and(BA6>$D$2,AZ6<$D$1),"2x, RD CIs very wide: Large harm to trivial effect or more","1x, RD CIs wide: crosses MID"),if(OR(AV6>=1.3,AV6<=0.7), if(and(count(AW6)=1,count(AX6)=1),if(round(AX6/AW6,2)>=2.5,"Wide OR CI: OIS not met","No serious imprecision"),"ERROR: check cell"),"No serious imprecision")),if(OR(AZ6<=(-1*$D$1),BA6>=$D$1),if(and(AZ6<(-1*$D$2),BA6>(-1*$D$1)),"2x, RD CIs very wide: Large benefit to trivial effect or more","1x, RD CIs wide: crosses MID"),if(OR(AV6>=1.3,AV6<=0.7), if(and(count(AW6)=1,count(AX6)=1),if(round(AX6/AW6,2)>=2.5,"Wide OR CI: OIS not met","No serious imprecision"),"ERROR: check cell"),"No serious imprecision")))),"ERROR: check cell") -> 1x, RD CIs wide: crosses MID | CK6: =if(AND(T6<1=TRUE,E6<1=TRUE)=TRUE,if(OR(AND(V6>G6=TRUE,G6>U6=TRUE),AND(G6>V6=TRUE,V6>F6=TRUE)=TRUE)=TRUE,"No serious incoherence","Quantitative incoherence (same direction of effect)"),if(AND(T6>1=TRUE,E6>1=TRUE)=TRUE,if(OR(AND(V6>G6=TRUE,G6>U6=TRUE),AND(G6>V6=TRUE,V6>F6=TRUE)=TRUE)=TRUE,"No serious incoherence","Quantitative incoherence (same direction of effect)"),if(OR(AND(T6<1=TRUE,E6>1=TRUE)=TRUE,AND(T6>1=TRUE,E6<1=TRUE)=TRUE)=TRUE,if(OR(AND(V6>G6=TRUE,G6>U6=TRUE),AND(G6>V6=TRUE,V6>F6=TRUE)=TRUE)=TRUE,"No serious incoherence","Qualitative incoherence (different direction of effect)")))) -> No serious incoherence | CL6: =AND(OR(AX6/G6<0.9,AX6/G6>1.1),OR(AW6/F6<0.9,AW6/F6>1.1)) -> TRUE | CM6: =AND(OR(AX6/V6<0.9,AX6/V6>1.1),OR(AW6/U6<0.9,AW6/U6>1.1)) -> FALSE | CN6: =(4-(3*COUNTIF(P6,"VERY LOW"))-2*countif(P6,"LOW")-1*countif(P6,"MODERATE")) -> 3 | CO6: =(4-(3*COUNTIF(AR6,"VERY LOW"))-2*countif(AR6,"LOW")-1*countif(AR6,"MODERATE")) -> 3 | CP6: =IFS(C6=Preferences!B$13,B6,B6=Preferences!B$13,C6) -> C
